{"uuid": "7c27d71f-0b57-4940-9cb5-a97936a09cd2", "children": ["d9a2b81d-0df2-412d-8443-3538c707a6e9"], "befores": [{"name": "_UnitTestCase__pytest_class_setup", "status": "broken", "statusDetails": {"message": "selenium.common.exceptions.WebDriverException: Message: An unknown server-side error occurred while processing the command. Original error: Cannot start the 'com.itcast.toutiaoApp' application. Visit https://github.com/appium/appium/blob/master/docs/en/writing-running-appium/android/activity-startup.md for troubleshooting. Original error: Activity name '.BrowserActivity' used to start the app doesn't exist or cannot be launched! Make sure it exists and is a launchable activity\n\n", "trace": "  File \"C:\\Users\\xuan\\AppData\\Local\\Programs\\Python\\Python36\\lib\\site-packages\\pluggy\\callers.py\", line 187, in _multicall\n    res = hook_impl.function(*args)\n  File \"C:\\Users\\xuan\\AppData\\Local\\Programs\\Python\\Python36\\lib\\site-packages\\_pytest\\fixtures.py\", line 1117, in pytest_fixture_setup\n    result = call_fixture_func(fixturefunc, request, kwargs)\n  File \"C:\\Users\\xuan\\AppData\\Local\\Programs\\Python\\Python36\\lib\\site-packages\\_pytest\\fixtures.py\", line 915, in call_fixture_func\n    fixture_result = next(generator)\n  File \"C:\\Users\\xuan\\AppData\\Local\\Programs\\Python\\Python36\\lib\\site-packages\\_pytest\\unittest.py\", line 131, in fixture\n    setup()\n  File \"E:\\heimaSoftTest\\Python_ClassCode\\UI_day11_hmtt_ui_test01\\case\\app\\test_query_aritcal.py\", line 13, in setUpClass\n    cls.driver = DriverUtils.get_app_driver()\n  File \"E:\\heimaSoftTest\\Python_ClassCode\\UI_day11_hmtt_ui_test01\\utils.py\", line 93, in get_app_driver\n    cls.__app_driver = appium.webdriver.Remote('http://localhost:4723/wd/hub', desired_caps)\n  File \"C:\\Users\\xuan\\AppData\\Local\\Programs\\Python\\Python36\\lib\\site-packages\\appium\\webdriver\\webdriver.py\", line 155, in __init__\n    proxy\n  File \"C:\\Users\\xuan\\AppData\\Local\\Programs\\Python\\Python36\\lib\\site-packages\\selenium\\webdriver\\remote\\webdriver.py\", line 157, in __init__\n    self.start_session(capabilities, browser_profile)\n  File \"C:\\Users\\xuan\\AppData\\Local\\Programs\\Python\\Python36\\lib\\site-packages\\appium\\webdriver\\webdriver.py\", line 225, in start_session\n    response = self.execute(RemoteCommand.NEW_SESSION, parameters)\n  File \"C:\\Users\\xuan\\AppData\\Local\\Programs\\Python\\Python36\\lib\\site-packages\\selenium\\webdriver\\remote\\webdriver.py\", line 321, in execute\n    self.error_handler.check_response(response)\n  File \"C:\\Users\\xuan\\AppData\\Local\\Programs\\Python\\Python36\\lib\\site-packages\\selenium\\webdriver\\remote\\errorhandler.py\", line 242, in check_response\n    raise exception_class(message, screen, stacktrace)\n"}, "start": 1598509678799, "stop": 1598509700736}], "start": 1598509678799, "stop": 1598509701069}